Workbook
Name Coverage_A: [1]Input!$C$21
Name Coverage_B: [1]Input!$C$22
Name Coverage_C: [1]Input!$C$23
Name Coverage_D: [1]Input!$C$24
Name Coverage_Liability: [1]Input!$C$28
Name Coverage_Medical: [1]Input!$C$29
Name Premium_Liability: [1]Input!$AD$27
Name Premium_Property: [1]Input!$AD$24
Name Property_Owner_Name: [1]Input!$D$7
Name Property_Owner_Street_Address: [1]Input!$D$11
Name Property_Owner_Zip_Code: [1]Input!$J$12
Name Property_Update_Roof: [1]Input!$I$31
Name Year_Built: [1]Input!$F$28

Sheet Rater
A1: Name of Insured: | B1: TEST CLIENT
A2: Business Address: | B2: 1 Main Street Suite 200
A3: Business Address City: | B3: Colorado Springs
A4: Business Address State: | B4: CO
A5: Business Address Zip: | B5: 80906
A6: Business Phone: | B6: 303-900-2960
A7: Business Web URL: | B7: www.one80.com
A11: STATE OF RISK | B11: CO | H11: Profile of Jobs | I11: Average hazard | J11: =VLOOKUP(I11,'Pick List'!J$21:K$24,2,FALSE)
A12: Class Description | B12: Animal Training Services | H12: management Credentials | I12: Below Average Hazard | J12: =VLOOKUP(I12,'Pick List'!J$21:K$24,2,FALSE)
A13: Base Rate | B13: 800 | H13: History of Disciplinary Actions | I13: Average hazard | J13: =VLOOKUP(I13,'Pick List'!J$21:K$24,2,FALSE)
A14: Rating Codes | B14: Selection | C14: Multiple | H14: Changes in Staff/Operations | I14: Average hazard | J14: =VLOOKUP(I14,'Pick List'!J$21:K$24,2,FALSE)
A15: Class | B15: =VLOOKUP(B12,Code!A1:B128,2,FALSE) | C15: 3 | H15: Industry Regulatory Environment | I15: Average hazard | J15: =VLOOKUP(I15,'Pick List'!J$21:K$24,2,FALSE)
A16: Revenue | B16: $3,000,001-$6,000,000 | C16: 2 | H16: Industry Issues | I16: Average hazard | J16: =VLOOKUP(I16,'Pick List'!J$21:K$24,2,FALSE)
A17: Longevity | B17: Less than 5 years in Business | C17: =VLOOKUP(B17,'Pick List'!A19:B21,2,FALSE) | H17: Internal Controls | I17: Average hazard | J17: =VLOOKUP(I17,'Pick List'!J$21:K$24,2,FALSE)
A18: Experience | B18: No claims, last 5 Years | C18: 3 | H18: Individual Risk TOTAL | J18: =J11*J12*J13*J14*J15*J16*J17
A19: Risk management | B19: Demonstrated use of favorable contracts | C19: =VLOOKUP(B19,'Pick List'!F24:G26,2,FALSE)
A20: Sub-Contracted Work | B20: Subcontracted Work less than or equal to 25% | C20: =VLOOKUP(B20,'Pick List'!F29:G31,2,FALSE) | H20: NOTE (If State specific feel free to overide cell C12)
A21: Retroactive Date | B21: Retro Date Inception | C21: =VLOOKUP(B21,'Pick List'!F33:G34,2,FALSE) | H21: IN DELAWARE MINIMUM IS .75 AND MAX IS 1.5 UNLESS USING E&S PAPER
A22: Individual Risk | B22: Carrier Multiple | C22: =IF(J18<0.5,0.5,IF(J18>1.5,1.5,J18)) | H22: IN IOWA MAX LIMIT IS +/- 25% for Individual Risk unless using E&S Paper
B23: RATING MULTIPLE | C23: =C15*C16*C17*C18*C19*C20*C21*C22 | H23: IN MARYLAND MINIMUM IS .75 AND MAX IS 1.5 UNLESS USING E&S PAPER
H24: IN MASSACHUSETTES MINIMUM IS .75 AND MAX IS 1.5 UNLESS USING E&S PAPER
A25: MINIMUM DEDUCTIBLE | B25: =VLOOKUP(B16,'Pick List'!A9:C17,3,FALSE) | C25: * For Revenue up to $3,000,000 and limits of MAX $1,000,000 a $1,000 Deductible is an option | H25: IN NORTH CAROLINA MINIMUM IS .75 AND MAX IS 1.5 UNLESS USING E&S PAPER
A26: DEDUCTIBLE SELECTED | B26: 5000 | H26: IN NORTH DAKOTA MINIMUM IS .75 AND MAX IS 1.5 UNLESS USING E&S PAPER
H27: IN OHIO MAX LIMIT IS +/- 25% for Individual Risk unless using E&S Paper
A28: RETRO DATE | C28: (Select RDI [retro Date Inception] or a Date
A31: Limit | B31: 1000000
A33: Deductible/Limit/Size | B33: =VLOOKUP('Pick List'!A41,Concatanate!F1:G315,2,FALSE)
C35: Rate | D35: Description
A36: Split Limit Option | B36: No Split | C36: =VLOOKUP(B36,'Pick List'!A44:C51,3,FALSE) | D36: =VLOOKUP(B36,'Pick List'!A44:B51,2,FALSE)
A38: FINAL MULIPLIER | B38: =C36*B33*C23
A40: PREMIUM | B40: =B38*B13
A43: CLASS | B43: EXAMPLE
A44: Class I | B44: Management Consulting, marketing Consulting, Education Consulting, Energy Conservation, Travel Agency, printers, Grant Writing, Interpreting, Translating
A45: Class II | B45: IT Consulting, Software Development, fullfillment Services, Agricultural Consulting, Event Planning
A46: Class III | B46: Medical Billing, Utility Billing, Other Billing, Employment Agencies, Staffing Firms, Auctioneer, Technical Energy Consulting, Background Screening, Custom Brokers, Freight Forwarders, Landscape Architects
A47: Class IV | B47: Surveyors, Franchisor services, Claims Adjusters, archeological consultants, Home Inspection Services, Other Inspection Services, Real Estate Agents, property Management, Construction Management (Non- GCs), Trustees, Receivers
A48: Class IV | B48: Certification Services, Safety Consultants, TPAs, Real Estate Appraisers, testing Labs, Inspectors with Heaby BI/PD exposure

Sheet Application
A6: Miscellaneous Professional Liability Program
A7: Old Republic Insurance
A9: INSURED: | B9: =Rater!B1
B10: =Rater!B2
B11: =Rater!B3 | E11: =Rater!B4 | F11: =Rater!B5
A13: We are pleased to offer the following indication which should be reviewed carefully. This is not a binder of insurance. The following information is a proposal and is to be presented without alteration.
A17: Real- Estate and CGL
A19: COVERAGE: | B19: Schedule reporting of individual Real Estate Owned/REI locations. Coverage applies to location as reported by the insured on the attached application.
A22: EXCLUSIONS: | B22: REFER TO POLICY FOR ALL OTHER EXCLUSIONS.
A24: TERM: | B24: 12 Months from Effective date of Binder unless otherwise negotiated.
A26: EFFECTIVE DATE: | C26: =[1]Input!A17
A28: AMOUNT OF INSURANCE: | C28: Maximum TIV per Certificate: $1,500,000 per Property [Excluding Cov B] - Commercial Property Form
C29: Maximum GL per Certificate: $1,000,000 per Occurrence / $2,000,000 Aggregate - Commercial GL
A30: Limits Requested:
B31: Coverage A: | C31: =Coverage_A
B32: Coverage B: | C32: =Coverage_B
B33: Coverage C: | C33: =Coverage_C
B34: Coverage D: | C34: =Coverage_D
B35: Coverage L: | C35: =Coverage_Liability
B36: Coverage M: | C36: =Coverage_Medical
A38: AOP Deductible: | B38: =[1]Data!C70
A39: Wind Deductible: | B39: =[1]Data!C71
A40: FLOOD | B40: Excluded
A41: QUAKE | B41: Excluded
A42: LOSS SETTLEMENT: | C42: Replacement Cost
A43: This policy is written on Excess and Surplus Lines Paper
A44: FLAT CANCELLATION IS NOT PERMITTED. PREMIUM AND TAX ARE 25% MINIMUM EARNED UPON REQUEST TO BIND. ALL FEES ARE FULLY EARNED AND NON-REFUNDABLE.
A48: Premium Property: | C48: =Premium_Property
A49: Premium Liability: | C49: =Premium_Liability
A50: Surplus Lines Tax | C50: =[1]Input!AE33
A51: Stamping Fee: | C51: =[1]Input!AE34
A52: Policy Fee : | C52: =[1]Input!AE35
A53: Inspection Fee : | C53: =[1]Input!AE36
A54: Florida Service Fee: | C54: =[1]Input!AE37
A55: EMPA: | C55: =[1]Input!AE38
A56: Will Comply Fee: | C56: =[1]Input!AE39
A57: TOTAL | C57: =SUM(C48:C56)
A58: Liability Exclusions:
A59: · Independent Contractor Exclusion
A60: · Professional Liability Exclusion
...

Sheet Pick List
A1: CLASS | B1: RATE | C1: Examples | P1: State
A2: Class I | B2: 1 | C2: Management Consulting, marketing Consulting, Education Consulting, Energy Conservation, Travel Agency, printers, Grant Writing, Interpreting, Translating | P2: AK
A3: Class II | B3: 1.5 | C3: IT Consulting, Software Development, fullfillment Services, Agricultural Consulting, Event Planning | P3: AL
A4: Class III | B4: 2 | C4: Medical Billing, Utility Billing, Other Billing, Employment Agencies, Staffing Firms, Auctioneer, Technical Energy Consulting, Background Screening, Custom Brokers, Freight Forwarders, Landscape Architects | P4: AR
A5: Class IV | B5: 3 | C5: Surveyors, Franchisor services, Claims Adjusters, archeological consultants, Home Inspection Services, Other Inspection Services, Real Estate Agents, property Management, Construction Management (Non- GCs), Trustees, Receivers | P5: AZ
A6: Class IV | B6: REFER | C6: Certification Services, Safety Consultants, TPAs, Real Estate Appraisers, testing Labs, Inspectors with Heaby BI/PD exposure | P6: CA
P7: CO
P8: CT
A9: $0-$250,000 | B9: 1 | C9: 2500 | F9: No claims, last 5 Years | G9: 1 | P9: DC
A10: $250,001-$500,000 | B10: 1.3 | C10: 2500 | F10: 1 claim withing retention, last 5 years | G10: 1.25 | P10: DE
A11: $500,001-$1,000,000 | B11: 1.6 | C11: 5000 | F11: 1 claim above retention, less than $50,000 last 5 years | G11: 1.5 | P11: FL
A12: $1,000,001-$3,000,000 | B12: 2 | C12: 5000 | F12: 1 claim above $50,000 and less than $100,000 last 5 years | G12: 2 | P12: GA
A13: $3,000,001-$6,000,000 | B13: 3 | C13: 10000 | F13: 1 claim $100,000 or more, last 5 years | G13: 3 | P13: HI
A14: $6,000,001-$10,000,000 | B14: 4 | C14: 10000 | F14: 2 claims within retention, last 5 years | G14: 1.5 | P14: IA
A15: $10,000,001-$20,000,000 | B15: 5 | C15: 25000 | F15: 2 or more claims, one or more above retention, less than $50,000, last 5 years | G15: 2 | P15: ID
A16: $20,000,001-$40,000,000 | B16: 6 | C16: 25000 | F16: 2 or more claims, one or more above $50,000, last 5 years | G16: 3 | P16: IL
A17: $40,000,001-$60,000,000 | B17: 7 | C17: 25000 | P17: IN
P18: KS
A19: 10 Years or more in Business | B19: 0.9 | P19: KY
A20: 5-10 Years in Business | B20: 1 | P20: LA
A21: Less than 5 years in Business | B21: 1.1 | J21: Below Average Hazard | K21: 0.75 | P21: MA
J22: Average hazard | K22: 1 | P22: MD
J23: Above Average Hazard | K23: 1.25 | P23: ME
F24: Demonstrated use of favorable contracts | G24: 0.9 | J24: Significantly Above Average Hazard | K24: 1.5 | P24: MI
F25: Adequate use of contracts | G25: 1 | P25: MN
A26: 500000 | F26: Less than adequate contract policies | G26: 1.1 | P26: MO
A27: 1000000 | P27: MS
A28: 2000000 | P28: MT
A29: 3000000 | F29: Subcontracted Work less than or equal to 25% | G29: 1 | P29: NC
A30: 5000000 | F30: Subcontracted Work greater than 25% and less than 50% | G30: 1.2 | P30: ND
F31: Subcontracted Work more than 50% | G31: 1.3 | P31: NE
P32: NH
A33: 1000 | F33: Retro Date Inception | G33: 0.9 | P33: NJ
A34: 2500 | F34: One Year or More Prior Acts | G34: 1 | P34: NM
A35: 5000 | P35: NV
A36: 10000 | P36: NY
A37: 25000 | P37: OH
A38: 50000 | P38: OK
A39: 100000 | P39: OR
P40: PA
...

Sheet Concatanate
A1: $0-$250,000 | B1: 1000 | C1: 500000 | D1: 0.85 | F1: =CONCATENATE(A1,B1,C1) | G1: 0.85
A2: $0-$250,000 | B2: 1000 | C2: 1000000 | D2: 1.1 | F2: =CONCATENATE(A2,B2,C2) | G2: 1.1
A3: $0-$250,000 | B3: 1000 | C3: 2000000 | D3: 99 | F3: =CONCATENATE(A3,B3,C3) | G3: 99
A4: $0-$250,000 | B4: 1000 | C4: 3000000 | D4: 99 | F4: =CONCATENATE(A4,B4,C4) | G4: 99
A5: $0-$250,000 | B5: 1000 | C5: 5000000 | D5: 99 | F5: =CONCATENATE(A5,B5,C5) | G5: 99
A6: $0-$250,000 | B6: 2500 | C6: 500000 | D6: 0.8 | F6: =CONCATENATE(A6,B6,C6) | G6: 0.8
A7: $0-$250,000 | B7: 2500 | C7: 1000000 | D7: 1.05 | F7: =CONCATENATE(A7,B7,C7) | G7: 1.05
A8: $0-$250,000 | B8: 2500 | C8: 2000000 | D8: 1.57 | F8: =CONCATENATE(A8,B8,C8) | G8: 1.57
A9: $0-$250,000 | B9: 2500 | C9: 3000000 | D9: 2 | F9: =CONCATENATE(A9,B9,C9) | G9: 2
A10: $0-$250,000 | B10: 2500 | C10: 5000000 | D10: 2.5 | F10: =CONCATENATE(A10,B10,C10) | G10: 2.5
A11: $0-$250,000 | B11: 5000 | C11: 500000 | D11: 0.76 | F11: =CONCATENATE(A11,B11,C11) | G11: 0.76
A12: $0-$250,000 | B12: 5000 | C12: 1000000 | D12: 1 | F12: =CONCATENATE(A12,B12,C12) | G12: 1
... A315: $40,000,001-$60,000,000 | B315: 100000 | C315: 5000000 | D315: 2.38 | F315: =CONCATENATE(A315,B315,C315) | G315: 2.38

Sheet Code
A1: Code | B1: Category
A2: Accident Reconstruction Services | B2: Class I
A3: Acoustic Consultant Services | B3: Class I
A4: Advertising Services / Media Services | B4: Class I
A5: Animal Training Services | B5: Class I
A6: Answering Service / Call Center Services / Paging Services | B6: Class I
A7: Anthologist Services | B7: Class I
A8: Anthropologist Services | B8: Class I
A9: Antique Dealer | B9: Class I
A10: Appraisal Services (Non-Real Estate) | B10: Class I
A11: Appraisal Services (Non-Real Estate) / Auctioneering Services (Non-Real Estate) | B11: Class I
A12: Arbitrator Services / Mediator Services | B12: Class I
... A128: Typing Services (Non-Medical) | B128: Class I

Sheet _Schema
A1: field | B1: cell | C1: type | D1: label | E1: direction | F1: group | G1: options | H1: default
A2: insured_name | B2: B1 | C2: text | D2: Insured Name | E2: input | F2: Client Info | H2: Test Client
A3: address | B3: B2 | C3: text | D3: Address | E3: input | F3: Client Info | H3: 1 Main Street Suite 200
A4: city | B4: B3 | C4: text | D4: City | E4: input | F4: Client Info | H4: Colorado Springs
A5: state | B5: B4 | C5: text | D5: State | E5: input | F5: Client Info | H5: CO
A6: zip | B6: B5 | C6: number | D6: Zip Code | E6: input | F6: Client Info | H6: 80906
A7: phone | B7: B6 | C7: text | D7: Phone | E7: input | F7: Client Info | H7: 303-900-2960
A8: web_url | B8: B7 | C8: text | D8: Web URL | E8: input | F8: Client Info | H8: www.one80.com
A9: state_of_risk | B9: B11 | C9: dropdown | D9: State of Risk | E9: input | F9: Rating Inputs | G9: AK;AL;AR;AZ;CA;CO;CT;DC;DE;FL;GA;HI;IA;ID;IL;IN;KS;KY;LA;MA;MD;ME;MI;MN;MO;MS;MT;NC;ND;NE;NH;NJ;NM;NV;NY;OH;OK;OR;PA;RI;SC;SD;TN;TX;UT;VA;VT;WA;WI;WV;WY | H9: CO
A10: class_description | B10: B12 | C10: text | D10: Class Description | E10: input | F10: Rating Inputs | H10: Animal Training Services
A11: base_rate | B11: B13 | C11: number | D11: Base Rate | E11: input | F11: Rating Inputs | H11: 800
A12: revenue | B12: B16 | C12: dropdown | D12: Annual Revenue | E12: input | F12: Rating Inputs | G12: $0-$250,000;$250,001-$500,000;$500,001-$1,000,000;$1,000,001-$3,000,000;$3,000,001-$6,000,000;$6,000,001-$10,000,000;$10,000,001-$20,000,000;$20,000,001-$40,000,000;$40,000,001-$60,000,000 | H12: $3,000,001-$6,000,000
A13: longevity | B13: B17 | C13: dropdown | D13: Longevity | E13: input | F13: Rating Inputs | G13: 10 Years or more in Business;5-10 Years in Business;Less than 5 years in Business | H13: Less than 5 years in Business
A14: experience | B14: B18 | C14: dropdown | D14: Claims Experience | E14: input | F14: Rating Inputs | G14: No claims, last 5 Years;1 claim withing retention, last 5 years;1 claim above retention, less than $50,000 last 5 years;1 claim above $50,000 and less than $100,000 last 5 years;1 claim $100,000 or more, last 5 years;2 claims within retention, last 5 years;2 or more claims, one or more above retention, less than $50,000, last 5 years;2 or more claims, one or more above $50,000, last 5 years | H14: No claims, last 5 Years
A15: risk_management | B15: B19 | C15: dropdown | D15: Risk Management | E15: input | F15: Rating Inputs | G15: Demonstrated use of favorable contracts;Adequate use of contracts;Less than adequate contract policies | H15: Demonstrated use of favorable contracts
A16: subcontracted | B16: B20 | C16: dropdown | D16: Subcontracted Work | E16: input | F16: Rating Inputs | G16: Subcontracted Work less than or equal to 25%;Subcontracted Work greater than 25% and less than 50%;Subcontracted Work more than 50% | H16: Subcontracted Work less than or equal to 25%
A17: retro_date | B17: B21 | C17: dropdown | D17: Retro Date | E17: input | F17: Rating Inputs | G17: Retro Date Inception;One Year or More Prior Acts | H17: Retro Date Inception
A18: deductible | B18: B26 | C18: dropdown | D18: Deductible | E18: input | F18: Rating Inputs | G18: 1000;2500;5000;10000;25000;50000;100000 | H18: 5000
A19: limit | B19: B31 | C19: dropdown | D19: Policy Limit | E19: input | F19: Rating Inputs | G19: 500000;1000000;2000000;3000000;5000000 | H19: 1000000
A20: split_limit | B20: B36 | C20: dropdown | D20: Split Limit | E20: input | F20: Rating Inputs | G20: No Split;500k/1M;1M/2M;1M/3M;1M/5M;2M/3M;2M/5M;3M/5M | H20: No Split
A21: profile_of_jobs | B21: I11 | C21: dropdown | D21: Profile of Jobs | E21: input | F21: Individual Risk Assessment | G21: Below Average Hazard;Average hazard;Above Average Hazard;Significantly Above Average Hazard | H21: Average hazard
A22: mgmt_credentials | B22: I12 | C22: dropdown | D22: Mgmt Credentials | E22: input | F22: Individual Risk Assessment | G22: Below Average Hazard;Average hazard;Above Average Hazard;Significantly Above Average Hazard | H22: Below Average Hazard
A23: disciplinary_history | B23: I13 | C23: dropdown | D23: Disciplinary History | E23: input | F23: Individual Risk Assessment | G23: Below Average Hazard;Average hazard;Above Average Hazard;Significantly Above Average Hazard | H23: Average hazard
... A27: internal_controls | B27: I17 | C27: dropdown | D27: Internal Controls | E27: input | F27: Individual Risk Assessment | G27: Below Average Hazard;Average hazard;Above Average Hazard;Significantly Above Average Hazard | H27: Average hazard
A28: premium | B28: B40 | C28: number | D28: Total Premium | E28: output | F28: Results
A29: final_multiplier | B29: B38 | C29: number | D29: Final Multiplier | E29: output | F29: Results
A30: rating_multiple | B30: C23 | C30: number | D30: Rating Multiple | E30: output | F30: Results
A31: carrier_multiple | B31: C22 | C31: number | D31: Carrier Multiple | E31: output | F31: Results
A32: individual_risk | B32: J18 | C32: number | D32: Individual Risk | E32: output | F32: Results
A33: min_deductible | B33: B25 | C33: number | D33: Min Deductible | E33: output | F33: Results
